<sdf version='1.7'>
  <world name='default'>
    <light name='sun' type='directional'>
      <cast_shadows>1</cast_shadows>
      <pose>0 0 10 0 -0 0</pose>
      <diffuse>0.8 0.8 0.8 1</diffuse>
      <specular>0.1 0.1 0.1 1</specular>
      <attenuation>
        <range>1000</range>
        <constant>0.9</constant>
        <linear>0.01</linear>
        <quadratic>0.001</quadratic>
      </attenuation>
      <direction>-0.5 0.5 -1</direction>
      <spot>
        <inner_angle>0</inner_angle>
        <outer_angle>0</outer_angle>
        <falloff>0</falloff>
      </spot>
    </light>
    <model name='ground_plane'>
      <static>1</static>
      <link name='link'>
        <collision name='collision'>
          <geometry>
            <plane>
              <normal>0 0 1</normal>
              <size>100 100</size>
            </plane>
          </geometry>
          <surface>
            <friction>
              <ode>
                <mu>100</mu>
                <mu2>50</mu2>
              </ode>
              <torsional>
                <ode/>
              </torsional>
            </friction>
            <contact>
              <ode/>
            </contact>
            <bounce/>
          </surface>
          <max_contacts>10</max_contacts>
        </collision>
        <visual name='visual'>
          <cast_shadows>0</cast_shadows>
          <geometry>
            <plane>
              <normal>0 0 1</normal>
              <size>100 100</size>
            </plane>
          </geometry>
          <material>
            <script>
              <uri>file://media/materials/scripts/gazebo.material</uri>
              <name>Gazebo/Grey</name>
            </script>
          </material>
        </visual>
        <self_collide>0</self_collide>
        <kinematic>0</kinematic>
        <gravity>1</gravity>
        <enable_wind>0</enable_wind>
      </link>
    </model>
    <gravity>0 0 -9.8</gravity>
    <magnetic_field>6e-06 2.3e-05 -4.2e-05</magnetic_field>
    <atmosphere type='adiabatic'/>
    <physics name='default_physics' default='0' type='ode'>
      <max_step_size>0.001</max_step_size>
      <real_time_factor>1</real_time_factor>
      <real_time_update_rate>1000</real_time_update_rate>
    </physics>
    <scene>
      <ambient>0.4 0.4 0.4 1</ambient>
      <background>0.7 0.7 0.7 1</background>
      <shadows>1</shadows>
    </scene>
    <spherical_coordinates>
      <surface_model>EARTH_WGS84</surface_model>
      <latitude_deg>0</latitude_deg>
      <longitude_deg>0</longitude_deg>
      <elevation>0</elevation>
      <heading_deg>0</heading_deg>
    </spherical_coordinates>
    <state world_name='default'>
      <sim_time>242 301000000</sim_time>
      <real_time>244 117412495</real_time>
      <wall_time>1766832723 396113773</wall_time>
      <iterations>242301</iterations>
      <model name='custom_wall'>
        <pose>2.75173 3.49602 0 0 -0 0</pose>
        <scale>1 1 1</scale>
        <link name='Wall_12'>
          <pose>6.00173 1.57102 0 0 -0 0</pose>
          <velocity>0 0 0 0 -0 0</velocity>
          <acceleration>0 0 0 0 -0 0</acceleration>
          <wrench>0 0 0 0 -0 0</wrench>
        </link>
        <link name='Wall_13'>
          <pose>10.0517 4.24602 0 0 -0 1.5708</pose>
          <velocity>0 0 0 0 -0 0</velocity>
          <acceleration>0 0 0 0 -0 0</acceleration>
          <wrench>0 0 0 0 -0 0</wrench>
        </link>
        <link name='Wall_14'>
          <pose>3.37673 6.92102 0 0 -0 3.14159</pose>
          <velocity>0 0 0 0 -0 0</velocity>
          <acceleration>0 0 0 0 -0 0</acceleration>
          <wrench>0 0 0 0 -0 0</wrench>
        </link>
        <link name='Wall_15'>
          <pose>-3.29827 2.24602 0 0 0 -1.5708</pose>
          <velocity>0 0 0 0 -0 0</velocity>
          <acceleration>0 0 0 0 -0 0</acceleration>
          <wrench>0 0 0 0 -0 0</wrench>
        </link>
        <link name='Wall_16'>
          <pose>4.75173 -2.42898 0 0 -0 0</pose>
          <velocity>0 0 0 0 -0 0</velocity>
          <acceleration>0 0 0 0 -0 0</acceleration>
          <wrench>0 0 0 0 -0 0</wrench>
        </link>
        <link name='Wall_17'>
          <pose>12.8017 3.49602 0 0 -0 1.5708</pose>
          <velocity>0 0 0 0 -0 0</velocity>
          <acceleration>0 0 0 0 -0 0</acceleration>
          <wrench>0 0 0 0 -0 0</wrench>
        </link>
        <link name='Wall_18'>
          <pose>2.75173 9.42102 0 0 -0 3.14159</pose>
          <velocity>0 0 0 0 -0 0</velocity>
          <acceleration>0 0 0 0 -0 0</acceleration>
          <wrench>0 0 0 0 -0 0</wrench>
        </link>
        <link name='Wall_19'>
          <pose>-7.29827 3.49602 0 0 0 -1.5708</pose>
          <velocity>0 0 0 0 -0 0</velocity>
          <acceleration>0 0 0 0 -0 0</acceleration>
          <wrench>0 0 0 0 -0 0</wrench>
        </link>
        <link name='Wall_20'>
          <pose>-5.29827 -2.42898 0 0 -0 0</pose>
          <velocity>0 0 0 0 -0 0</velocity>
          <acceleration>0 0 0 0 -0 0</acceleration>
          <wrench>0 0 0 0 -0 0</wrench>
        </link>
      </model>
      <model name='go2'>
        <pose>0.125469 0.006817 0.214457 0.002751 0.001665 0.016226</pose>
        <scale>1 1 1</scale>
        <link name='base_link'>
          <pose>0.125469 0.006817 0.214457 0.002751 0.001665 0.016226</pose>
          <velocity>0.001512 -0.000898 -0.002036 0.067834 -0.034208 -0.007503</velocity>
          <acceleration>-8.31114 -4.16582 -9.44334 -3.03961 0.461989 2.24141</acceleration>
          <wrench>-64.511 -32.3351 -73.2992 0 -0 0</wrench>
        </link>
        <link name='lf_hip_link'>
          <pose>0.318089 0.056449 0.214262 0.034368 0.001665 0.016291</pose>
          <velocity>0.001892 -0.002296 0.008207 0.000788 -0.036143 -0.040163</velocity>
          <acceleration>-6.25889 -8.39013 0.119735 1.82514 -0.115461 -2.6201</acceleration>
          <wrench>-4.24353 -5.68851 0.08118 0 -0 0</wrench>
        </link>
        <link name='lf_lower_leg_link'>
          <pose>0.135102 0.152773 0.105978 0.076425 -1.09215 -0.051866</pose>
          <velocity>0.129532 0.013061 -0.195963 2.66835 -0.783934 -2.9156</velocity>
          <acceleration>-20.8074 5.21094 -188.816 1.82616 -1.1602 0.371569</acceleration>
          <wrench>-4.45277 1.11514 -40.4067 0 -0 0</wrench>
        </link>
        <link name='lf_upper_leg_link'>
          <pose>0.316548 0.15188 0.217535 0.06553 1.01823 0.07204</pose>
          <velocity>0.001619 -0.00213 0.012703 0.016006 -1.14588 -0.082778</velocity>
          <acceleration>0.684908 -6.07017 -5.62199 1.89816 1.02748 -0.078228</acceleration>
          <wrench>0.789014 -6.99283 -6.47654 0 -0 0</wrench>
        </link>
        <link name='lh_hip_link'>
          <pose>-0.06866 0.050174 0.214905 0.031228 0.001656 0.016344</pose>
          <velocity>0.001838 0.000537 -0.005972 -0.097073 -0.038731 0.029377</velocity>
          <acceleration>-6.58559 3.75712 -18.7044 -2.25921 -0.524702 -0.169722</acceleration>
          <wrench>-4.46503 2.54732 -12.6816 0 -0 0</wrench>
        </link>
        <link name='lh_lower_leg_link'>
          <pose>-0.251688 0.146144 0.106386 0.069658 -1.08586 -0.04566</pose>
          <velocity>0.013498 -0.012609 -0.034318 0.181009 -0.232551 -0.036725</velocity>
          <acceleration>113.012 -2.94748 908.058 1.72782 -0.487333 2.52312</acceleration>
          <wrench>24.1845 -0.63076 194.324 0 -0 0</wrench>
        </link>
        <link name='lh_upper_leg_link'>
          <pose>-0.0702 0.145616 0.217872 0.059597 1.01884 0.067068</pose>
          <velocity>0.003628 0.001126 -0.018567 -0.094116 -0.088175 0.028642</velocity>
          <acceleration>-25.652 2.33977 30.4991 0.014573 -0.002166 1.57454</acceleration>
          <wrench>-29.5511 2.69542 35.135 0 -0 0</wrench>
        </link>
        <link name='rf_hip_link'>
          <pose>0.319597 -0.036538 0.214005 -0.033092 0.001672 0.016061</pose>
          <velocity>0.001196 -0.00234 0.001158 0.123781 -0.031365 -0.044421</velocity>
          <acceleration>-9.52637 -8.26533 -4.71617 -0.851909 1.25269 -1.03976</acceleration>
          <wrench>-6.45888 -5.6039 -3.19756 0 -0 0</wrench>
        </link>
        <link name='rf_lower_leg_link'>
          <pose>0.140499 -0.138617 0.104501 -0.076875 -1.09589 0.085032</pose>
          <velocity>-0.007102 0.018099 -0.003978 -0.197411 -0.068809 0.014805</velocity>
          <acceleration>141.766 -16.2748 941.995 -2.0172 -0.38813 -1.89881</acceleration>
          <wrench>30.3379 -3.4828 201.587 0 -0 0</wrench>
        </link>
        <link name='rf_upper_leg_link'>
          <pose>0.321156 -0.131973 0.217138 -0.062509 1.01236 -0.036947</pose>
          <velocity>0.001304 -0.002504 -0.015752 0.120445 0.067619 -0.05317</velocity>
          <acceleration>-29.9156 -6.12221 42.0318 -2.87655 -1.32929 1.25971</acceleration>
          <wrench>-34.4628 -7.05278 48.4206 0 -0 0</wrench>
        </link>
        <link name='rh_hip_link'>
          <pose>-0.067151 -0.042815 0.214651 -0.021842 0.001665 0.016242</pose>
          <velocity>0.00107 0.000354 -0.011854 0.073061 -0.033645 -0.000906</velocity>
          <acceleration>-9.6646 3.31324 -22.3915 -1.52049 -0.196253 2.91696</acceleration>
          <wrench>-6.5526 2.24638 -15.1814 0 -0 0</wrench>
        </link>
        <link name='rh_lower_leg_link'>
          <pose>-0.245771 -0.143683 0.103257 -0.05024 -1.10294 0.061243</pose>
          <velocity>-0.008797 0.012578 -0.006331 -0.167805 -0.087278 0.026068</velocity>
          <acceleration>175.309 4.3609 935.808 -0.169043 0.959321 -1.31352</acceleration>
          <wrench>37.516 0.933232 200.263 0 -0 0</wrench>
        </link>
        <link name='rh_upper_leg_link'>
          <pose>-0.065594 -0.138279 0.216728 -0.04091 1.00844 -0.018378</pose>
          <velocity>0.001877 0.0002 -0.02215 0.09052 0.09036 -0.021165</velocity>
          <acceleration>-28.7719 4.28943 20.0259 -1.72966 -0.62008 -2.14519</acceleration>
          <wrench>-33.1452 4.94143 23.0698 0 -0 0</wrench>
        </link>
      </model>
      <model name='ground_plane'>
        <pose>0 0 0 0 -0 0</pose>
        <scale>1 1 1</scale>
        <link name='link'>
          <pose>0 0 0 0 -0 0</pose>
          <velocity>0 0 0 0 -0 0</velocity>
          <acceleration>0 0 0 0 -0 0</acceleration>
          <wrench>0 0 0 0 -0 0</wrench>
        </link>
      </model>
      <light name='sun'>
        <pose>0 0 10 0 -0 0</pose>
      </light>
    </state>
    <gui fullscreen='0'>
      <camera name='user_camera'>
        <pose>0.601065 0.071462 13.2295 -4e-06 1.5698 1.65618</pose>
        <view_controller>orbit</view_controller>
        <projection_type>perspective</projection_type>
      </camera>
    </gui>
    <audio>
      <device>default</device>
    </audio>
    <wind/>
    <model name='go2'>
      <link name='base_link'>
        <inertial>
          <pose>0.040468 0 0.007755 0 -0 0</pose>
          <mass>7.762</mass>
          <inertia>
            <ixx>0.0364988</ixx>
            <ixy>0.00012166</ixy>
            <ixz>-0.0147616</ixz>
            <iyy>0.134069</iyy>
            <iyz>-3.12e-05</iyz>
            <izz>0.132178</izz>
          </inertia>
        </inertial>
        <collision name='base_link_fixed_joint_lump__trunk_collision'>
          <pose>0 0 0 0 -0 0</pose>
          <geometry>
            <box>
              <size>0.3762 0.0935 0.114</size>
            </box>
          </geometry>
          <surface>
            <contact>
              <ode>
                <kp>10000</kp>
                <kd>1</kd>
              </ode>
            </contact>
            <friction>
              <ode>
                <mu>0.2</mu>
                <mu2>0.2</mu2>
              </ode>
              <torsional>
                <ode/>
              </torsional>
            </friction>
            <bounce/>
          </surface>
          <max_contacts>10</max_contacts>
        </collision>
        <collision name='base_link_fixed_joint_lump__imu_link_collision_1'>
          <pose>0 0 0 0 -0 0</pose>
          <geometry>
            <box>
              <size>0.001 0.001 0.001</size>
            </box>
          </geometry>
          <surface>
            <contact>
              <ode/>
            </contact>
            <friction>
              <ode/>
              <torsional>
                <ode/>
              </torsional>
            </friction>
            <bounce/>
          </surface>
          <max_contacts>10</max_contacts>
        </collision>
        <collision name='base_link_fixed_joint_lump__velodyne_base_link_collision_2'>
          <pose>0.2 0 0.11585 0 -0 0</pose>
          <geometry>
            <cylinder>
              <length>0.0717</length>
              <radius>0.0516</radius>
            </cylinder>
          </geometry>
          <max_contacts>10</max_contacts>
          <surface>
            <contact>
              <ode/>
            </contact>
            <bounce/>
            <friction>
              <torsional>
                <ode/>
              </torsional>
              <ode/>
            </friction>
          </surface>
        </collision>
        <visual name='base_link_visual'>
          <pose>0 0 0 0 -0 0</pose>
          <geometry>
            <box>
              <size>0.001 0.001 0.001</size>
            </box>
          </geometry>
        </visual>
        <visual name='base_link_fixed_joint_lump__trunk_visual_1'>
          <pose>0 0 0 0 -0 0</pose>
          <geometry>
            <mesh>
              <scale>1 1 1</scale>
              <uri>file:///home/zyme/ros_ws/go2_sim/install/go2_description/share/go2_description/meshes/trunk.dae</uri>
            </mesh>
          </geometry>
        </visual>
        <visual name='base_link_fixed_joint_lump__imu_link_visual_2'>
          <pose>0 0 0 0 -0 0</pose>
          <geometry>
            <box>
              <size>0.001 0.001 0.001</size>
            </box>
          </geometry>
        </visual>
        <visual name='base_link_fixed_joint_lump__velodyne_base_link_visual_3'>
          <pose>0.2 0 0.08 0 -0 0</pose>
          <geometry>
            <mesh>
              <scale>1 1 1</scale>
              <uri>file:///opt/ros/humble/share/velodyne_description/meshes/VLP16_base_1.dae</uri>
            </mesh>
          </geometry>
        </visual>
        <visual name='base_link_fixed_joint_lump__velodyne_base_link_visual_4'>
          <pose>0.2 0 0.08 0 -0 0</pose>
          <geometry>
            <mesh>
              <scale>1 1 1</scale>
              <uri>file:///opt/ros/humble/share/velodyne_description/meshes/VLP16_base_2.dae</uri>
            </mesh>
          </geometry>
        </visual>
        <visual name='base_link_fixed_joint_lump__velodyne_visual_5'>
          <pose>0.2 0 0.08 0 -0 0</pose>
          <geometry>
            <mesh>
              <scale>1 1 1</scale>
              <uri>file:///opt/ros/humble/share/velodyne_description/meshes/VLP16_scan.dae</uri>
            </mesh>
          </geometry>
        </visual>
        <sensor name='imu_sensor' type='imu'>
          <always_on>1</always_on>
          <update_rate>100</update_rate>
          <imu>
            <angular_velocity>
              <x>
                <noise type='gaussian'>
                  <mean>0</mean>
                  <stddev>0.0002</stddev>
                </noise>
              </x>
              <y>
                <noise type='gaussian'>
                  <mean>0</mean>
                  <stddev>0.0002</stddev>
                </noise>
              </y>
              <z>
                <noise type='gaussian'>
                  <mean>0</mean>
                  <stddev>0.0002</stddev>
                </noise>
              </z>
            </angular_velocity>
            <linear_acceleration>
              <x>
                <noise type='gaussian'>
                  <mean>0</mean>
                  <stddev>0.017</stddev>
                </noise>
              </x>
              <y>
                <noise type='gaussian'>
                  <mean>0</mean>
                  <stddev>0.017</stddev>
                </noise>
              </y>
              <z>
                <noise type='gaussian'>
                  <mean>0</mean>
                  <stddev>0.017</stddev>
                </noise>
              </z>
            </linear_acceleration>
          </imu>
          <plugin name='imu_plugin' filename='libgazebo_ros_imu_sensor.so'>
            <ros>
              <namespace>imu</namespace>
              <remapping>~/out:=data</remapping>
            </ros>
            <initial_orientation_as_reference>0</initial_orientation_as_reference>
          </plugin>
          <pose>0 0 0 0 -0 0</pose>
        </sensor>
        <sensor name='velodyne-VLP16' type='ray'>
          <visualize>0</visualize>
          <update_rate>10</update_rate>
          <ray>
            <scan>
              <horizontal>
                <samples>440</samples>
                <resolution>1</resolution>
                <min_angle>-3.14159</min_angle>
                <max_angle>3.14159</max_angle>
              </horizontal>
              <vertical>
                <samples>16</samples>
                <resolution>1</resolution>
                <min_angle>-0.261799</min_angle>
                <max_angle>0.261799</max_angle>
              </vertical>
            </scan>
            <range>
              <min>0.3</min>
              <max>131</max>
              <resolution>0.001</resolution>
            </range>
            <noise>
              <type>gaussian</type>
              <mean>0</mean>
              <stddev>0</stddev>
            </noise>
          </ray>
          <plugin name='gazebo_ros_laser_controller' filename='libgazebo_ros_velodyne_laser.so'>
            <ros>
              <namespace>/</namespace>
              <remapping>~/out:=velodyne_points</remapping>
            </ros>
            <frame_name>velodyne</frame_name>
            <organize_cloud>0</organize_cloud>
            <min_range>0.9</min_range>
            <max_range>130.0</max_range>
            <gaussian_noise>0.008</gaussian_noise>
          </plugin>
          <pose>0.2 0 0.1177 0 -0 0</pose>
        </sensor>
        <self_collide>0</self_collide>
        <enable_wind>0</enable_wind>
        <kinematic>0</kinematic>
      </link>
      <joint name='lf_hip_joint' type='revolute'>
        <pose relative_to='base_link'>0.1934 0.0465 0 0 -0 0</pose>
        <parent>base_link</parent>
        <child>lf_hip_link</child>
        <axis>
          <xyz>1 0 0</xyz>
          <limit>
            <lower>-1.0472</lower>
            <upper>1.0472</upper>
            <effort>23.7</effort>
            <velocity>30.1</velocity>
          </limit>
          <dynamics>
            <damping>0.01</damping>
            <friction>0.2</friction>
            <spring_reference>0</spring_reference>
            <spring_stiffness>0</spring_stiffness>
          </dynamics>
        </axis>
      </joint>
      <link name='lf_hip_link'>
        <pose relative_to='lf_hip_joint'>0 0 0 0 -0 0</pose>
        <inertial>
          <pose>-0.0054 0.00194 -0.000105 0 -0 0</pose>
          <mass>0.678</mass>
          <inertia>
            <ixx>0.00048</ixx>
            <ixy>-3.01e-06</ixy>
            <ixz>1.11e-06</ixz>
            <iyy>0.000884</iyy>
            <iyz>-1.42e-06</iyz>
            <izz>0.000596</izz>
          </inertia>
        </inertial>
        <collision name='lf_hip_link_collision'>
          <pose>0 0.0955 0 1.5708 -0 0</pose>
          <geometry>
            <cylinder>
              <length>0.04</length>
              <radius>0.046</radius>
            </cylinder>
          </geometry>
          <surface>
            <contact>
              <ode/>
            </contact>
            <friction>
              <ode>
                <mu>0.2</mu>
                <mu2>0.2</mu2>
              </ode>
              <torsional>
                <ode/>
              </torsional>
            </friction>
            <bounce/>
          </surface>
          <max_contacts>10</max_contacts>
        </collision>
        <visual name='lf_hip_link_visual'>
          <pose>0 0 0 0 -0 0</pose>
          <geometry>
            <mesh>
              <scale>1 1 1</scale>
              <uri>file:///home/zyme/ros_ws/go2_sim/install/go2_description/share/go2_description/meshes/hip.dae</uri>
            </mesh>
          </geometry>
        </visual>
        <self_collide>0</self_collide>
        <enable_wind>0</enable_wind>
        <kinematic>0</kinematic>
      </link>
      <joint name='lf_upper_leg_joint' type='revolute'>
        <pose relative_to='lf_hip_link'>0 0.0955 0 0 -0 0</pose>
        <parent>lf_hip_link</parent>
        <child>lf_upper_leg_link</child>
        <axis>
          <xyz>0 1 0</xyz>
          <limit>
            <lower>-1.5708</lower>
            <upper>3.4907</upper>
            <effort>23.7</effort>
            <velocity>30.1</velocity>
          </limit>
          <dynamics>
            <damping>0.01</damping>
            <friction>0.2</friction>
            <spring_reference>0</spring_reference>
            <spring_stiffness>0</spring_stiffness>
          </dynamics>
        </axis>
      </joint>
      <link name='lf_upper_leg_link'>
        <pose relative_to='lf_upper_leg_joint'>0 0 0 0 -0 0</pose>
        <inertial>
          <pose>-0.00374 -0.0223 -0.0327 0 -0 0</pose>
          <mass>1.152</mass>
          <inertia>
            <ixx>0.00584</ixx>
            <ixy>8.72e-05</ixy>
            <ixz>-0.000289</ixz>
            <iyy>0.0058</iyy>
            <iyz>0.000808</iyz>
            <izz>0.00103</izz>
          </inertia>
        </inertial>
        <collision name='lf_upper_leg_link_collision'>
          <pose>0 0 -0.1065 3.14159 1.57079 3.14159</pose>
          <geometry>
            <box>
              <size>0.213 0.0245 0.034</size>
            </box>
          </geometry>
          <surface>
            <contact>
              <ode>
                <kp>10000</kp>
                <kd>1</kd>
              </ode>
            </contact>
            <friction>
              <ode>
                <mu>0.2</mu>
                <mu2>0.2</mu2>
              </ode>
              <torsional>
                <ode/>
              </torsional>
            </friction>
            <bounce/>
          </surface>
          <max_contacts>10</max_contacts>
        </collision>
        <visual name='lf_upper_leg_link_visual'>
          <pose>0 0 0 0 -0 0</pose>
          <geometry>
            <mesh>
              <scale>1 1 1</scale>
              <uri>file:///home/zyme/ros_ws/go2_sim/install/go2_description/share/go2_description/meshes/thigh.dae</uri>
            </mesh>
          </geometry>
        </visual>
        <self_collide>1</self_collide>
        <enable_wind>0</enable_wind>
        <kinematic>0</kinematic>
      </link>
      <joint name='lf_lower_leg_joint' type='revolute'>
        <pose relative_to='lf_upper_leg_link'>0 0 -0.213 0 -0 0</pose>
        <parent>lf_upper_leg_link</parent>
        <child>lf_lower_leg_link</child>
        <axis>
          <xyz>0 1 0</xyz>
          <limit>
            <lower>-2.7227</lower>
            <upper>-0.83776</upper>
            <effort>35.55</effort>
            <velocity>20.06</velocity>
          </limit>
          <dynamics>
            <damping>0.01</damping>
            <friction>0.2</friction>
            <spring_reference>0</spring_reference>
            <spring_stiffness>0</spring_stiffness>
          </dynamics>
        </axis>
      </joint>
      <link name='lf_lower_leg_link'>
        <pose relative_to='lf_lower_leg_joint'>0 0 0 0 -0 0</pose>
        <inertial>
          <pose>0.003944 -0.000702 -0.142477 0 -0 0</pose>
          <mass>0.214</mass>
          <inertia>
            <ixx>0.00150432</ixx>
            <ixy>5.70698e-07</ixy>
            <ixz>-5.98808e-06</ixz>
            <iyy>0.00152557</iyy>
            <iyz>1.24056e-05</iyz>
            <izz>4.38377e-05</izz>
          </inertia>
        </inertial>
        <collision name='lf_lower_leg_link_collision'>
          <pose>0 0 -0.1065 3.14159 1.57079 3.14159</pose>
          <geometry>
            <box>
              <size>0.213 0.016 0.016</size>
            </box>
          </geometry>
          <surface>
            <contact>
              <ode/>
            </contact>
            <friction>
              <ode>
                <mu>0.2</mu>
                <mu2>0.2</mu2>
              </ode>
              <torsional>
                <ode/>
              </torsional>
            </friction>
            <bounce/>
          </surface>
          <max_contacts>10</max_contacts>
        </collision>
        <collision name='lf_lower_leg_link_fixed_joint_lump__lf_foot_link_collision_1'>
          <pose>0 0 -0.213 0 -0 0</pose>
          <geometry>
            <sphere>
              <radius>0.02</radius>
            </sphere>
          </geometry>
          <surface>
            <contact>
              <ode>
                <kp>10000</kp>
                <kd>1</kd>
              </ode>
            </contact>
            <friction>
              <ode>
                <mu>0.6</mu>
                <mu2>0.6</mu2>
              </ode>
              <torsional>
                <ode/>
              </torsional>
            </friction>
            <bounce/>
          </surface>
          <max_contacts>10</max_contacts>
        </collision>
        <visual name='lf_lower_leg_link_visual'>
          <pose>0 0 0 0 -0 0</pose>
          <geometry>
            <mesh>
              <scale>1 1 1</scale>
              <uri>file:///home/zyme/ros_ws/go2_sim/install/go2_description/share/go2_description/meshes/calf.dae</uri>
            </mesh>
          </geometry>
        </visual>
        <visual name='lf_lower_leg_link_fixed_joint_lump__lf_foot_link_visual_1'>
          <pose>0 0 -0.213 0 -0 0</pose>
          <geometry>
            <sphere>
              <radius>0.01</radius>
            </sphere>
          </geometry>
        </visual>
        <self_collide>1</self_collide>
        <self_collide>1</self_collide>
        <enable_wind>0</enable_wind>
        <kinematic>0</kinematic>
      </link>
      <joint name='lh_hip_joint' type='revolute'>
        <pose relative_to='base_link'>-0.1934 0.0465 0 0 -0 0</pose>
        <parent>base_link</parent>
        <child>lh_hip_link</child>
        <axis>
          <xyz>1 0 0</xyz>
          <limit>
            <lower>-1.0472</lower>
            <upper>1.0472</upper>
            <effort>23.7</effort>
            <velocity>30.1</velocity>
          </limit>
          <dynamics>
            <damping>0.01</damping>
            <friction>0.2</friction>
            <spring_reference>0</spring_reference>
            <spring_stiffness>0</spring_stiffness>
          </dynamics>
        </axis>
      </joint>
      <link name='lh_hip_link'>
        <pose relative_to='lh_hip_joint'>0 0 0 0 -0 0</pose>
        <inertial>
          <pose>0.0054 0.00194 -0.000105 0 -0 0</pose>
          <mass>0.678</mass>
          <inertia>
            <ixx>0.00048</ixx>
            <ixy>3.01e-06</ixy>
            <ixz>-1.11e-06</ixz>
            <iyy>0.000884</iyy>
            <iyz>-1.42e-06</iyz>
            <izz>0.000596</izz>
          </inertia>
        </inertial>
        <collision name='lh_hip_link_collision'>
          <pose>0 0.0955 0 1.5708 -0 0</pose>
          <geometry>
            <cylinder>
              <length>0.04</length>
              <radius>0.046</radius>
            </cylinder>
          </geometry>
          <max_contacts>10</max_contacts>
          <surface>
            <contact>
              <ode/>
            </contact>
            <bounce/>
            <friction>
              <torsional>
                <ode/>
              </torsional>
              <ode/>
            </friction>
          </surface>
        </collision>
        <visual name='lh_hip_link_visual'>
          <pose>0 0 0 3.14159 -0 3.14159</pose>
          <geometry>
            <mesh>
              <scale>1 1 1</scale>
              <uri>file:///home/zyme/ros_ws/go2_sim/install/go2_description/share/go2_description/meshes/hip.dae</uri>
            </mesh>
          </geometry>
        </visual>
        <self_collide>0</self_collide>
        <enable_wind>0</enable_wind>
        <kinematic>0</kinematic>
      </link>
      <joint name='lh_upper_leg_joint' type='revolute'>
        <pose relative_to='lh_hip_link'>0 0.0955 0 0 -0 0</pose>
        <parent>lh_hip_link</parent>
        <child>lh_upper_leg_link</child>
        <axis>
          <xyz>0 1 0</xyz>
          <limit>
            <lower>-1.5708</lower>
            <upper>3.4907</upper>
            <effort>23.7</effort>
            <velocity>30.1</velocity>
          </limit>
          <dynamics>
            <damping>0.01</damping>
            <friction>0.2</friction>
            <spring_reference>0</spring_reference>
            <spring_stiffness>0</spring_stiffness>
          </dynamics>
        </axis>
      </joint>
      <link name='lh_upper_leg_link'>
        <pose relative_to='lh_upper_leg_joint'>0 0 0 0 -0 0</pose>
        <inertial>
          <pose>-0.00374 -0.0223 -0.0327 0 -0 0</pose>
          <mass>1.152</mass>
          <inertia>
            <ixx>0.00584</ixx>
            <ixy>8.72e-05</ixy>
            <ixz>-0.000289</ixz>
            <iyy>0.0058</iyy>
            <iyz>0.000808</iyz>
            <izz>0.00103</izz>
          </inertia>
        </inertial>
        <collision name='lh_upper_leg_link_collision'>
          <pose>0 0 -0.1065 3.14159 1.57079 3.14159</pose>
          <geometry>
            <box>
              <size>0.213 0.0245 0.034</size>
            </box>
          </geometry>
          <surface>
            <contact>
              <ode>
                <kp>10000</kp>
                <kd>1</kd>
              </ode>
            </contact>
            <friction>
              <ode>
                <mu>0.2</mu>
                <mu2>0.2</mu2>
              </ode>
              <torsional>
                <ode/>
              </torsional>
            </friction>
            <bounce/>
          </surface>
          <max_contacts>10</max_contacts>
        </collision>
        <visual name='lh_upper_leg_link_visual'>
          <pose>0 0 0 0 -0 0</pose>
          <geometry>
            <mesh>
              <scale>1 1 1</scale>
              <uri>file:///home/zyme/ros_ws/go2_sim/install/go2_description/share/go2_description/meshes/thigh.dae</uri>
            </mesh>
          </geometry>
        </visual>
        <self_collide>1</self_collide>
        <enable_wind>0</enable_wind>
        <kinematic>0</kinematic>
      </link>
      <joint name='lh_lower_leg_joint' type='revolute'>
        <pose relative_to='lh_upper_leg_link'>0 0 -0.213 0 -0 0</pose>
        <parent>lh_upper_leg_link</parent>
        <child>lh_lower_leg_link</child>
        <axis>
          <xyz>0 1 0</xyz>
          <limit>
            <lower>-2.7227</lower>
            <upper>-0.83776</upper>
            <effort>35.55</effort>
            <velocity>20.06</velocity>
          </limit>
          <dynamics>
            <damping>0.01</damping>
            <friction>0.2</friction>
            <spring_reference>0</spring_reference>
            <spring_stiffness>0</spring_stiffness>
          </dynamics>
        </axis>
      </joint>
      <link name='lh_lower_leg_link'>
        <pose relative_to='lh_lower_leg_joint'>0 0 0 0 -0 0</pose>
        <inertial>
          <pose>0.003944 -0.000702 -0.142477 0 -0 0</pose>
          <mass>0.214</mass>
          <inertia>
            <ixx>0.00150432</ixx>
            <ixy>5.70698e-07</ixy>
            <ixz>-5.98808e-06</ixz>
            <iyy>0.00152557</iyy>
            <iyz>1.24056e-05</iyz>
            <izz>4.38377e-05</izz>
          </inertia>
        </inertial>
        <collision name='lh_lower_leg_link_collision'>
          <pose>0 0 -0.1065 3.14159 1.57079 3.14159</pose>
          <geometry>
            <box>
              <size>0.213 0.016 0.016</size>
            </box>
          </geometry>
          <surface>
            <contact>
              <ode/>
            </contact>
            <friction>
              <ode>
                <mu>0.2</mu>
                <mu2>0.2</mu2>
              </ode>
              <torsional>
                <ode/>
              </torsional>
            </friction>
            <bounce/>
          </surface>
          <max_contacts>10</max_contacts>
        </collision>
        <collision name='lh_lower_leg_link_fixed_joint_lump__lh_foot_link_collision_1'>
          <pose>0 0 -0.213 0 -0 0</pose>
          <geometry>
            <sphere>
              <radius>0.02</radius>
            </sphere>
          </geometry>
          <surface>
            <contact>
              <ode>
                <kp>10000</kp>
                <kd>1</kd>
              </ode>
            </contact>
            <friction>
              <ode>
                <mu>0.6</mu>
                <mu2>0.6</mu2>
              </ode>
              <torsional>
                <ode/>
              </torsional>
            </friction>
            <bounce/>
          </surface>
          <max_contacts>10</max_contacts>
        </collision>
        <visual name='lh_lower_leg_link_visual'>
          <pose>0 0 0 0 -0 0</pose>
          <geometry>
            <mesh>
              <scale>1 1 1</scale>
              <uri>file:///home/zyme/ros_ws/go2_sim/install/go2_description/share/go2_description/meshes/calf.dae</uri>
            </mesh>
          </geometry>
        </visual>
        <visual name='lh_lower_leg_link_fixed_joint_lump__lh_foot_link_visual_1'>
          <pose>0 0 -0.213 0 -0 0</pose>
          <geometry>
            <sphere>
              <radius>0.01</radius>
            </sphere>
          </geometry>
        </visual>
        <self_collide>1</self_collide>
        <self_collide>1</self_collide>
        <enable_wind>0</enable_wind>
        <kinematic>0</kinematic>
      </link>
      <joint name='rf_hip_joint' type='revolute'>
        <pose relative_to='base_link'>0.1934 -0.0465 0 0 -0 0</pose>
        <parent>base_link</parent>
        <child>rf_hip_link</child>
        <axis>
          <xyz>1 0 0</xyz>
          <limit>
            <lower>-1.0472</lower>
            <upper>1.0472</upper>
            <effort>23.7</effort>
            <velocity>30.1</velocity>
          </limit>
          <dynamics>
            <damping>0.01</damping>
            <friction>0.2</friction>
            <spring_reference>0</spring_reference>
            <spring_stiffness>0</spring_stiffness>
          </dynamics>
        </axis>
      </joint>
      <link name='rf_hip_link'>
        <pose relative_to='rf_hip_joint'>0 0 0 0 -0 0</pose>
        <inertial>
          <pose>-0.0054 -0.00194 -0.000105 0 -0 0</pose>
          <mass>0.678</mass>
          <inertia>
            <ixx>0.00048</ixx>
            <ixy>3.01e-06</ixy>
            <ixz>1.11e-06</ixz>
            <iyy>0.000884</iyy>
            <iyz>1.42e-06</iyz>
            <izz>0.000596</izz>
          </inertia>
        </inertial>
        <collision name='rf_hip_link_collision'>
          <pose>0 -0.0955 0 1.5708 -0 0</pose>
          <geometry>
            <cylinder>
              <length>0.04</length>
              <radius>0.046</radius>
            </cylinder>
          </geometry>
          <max_contacts>10</max_contacts>
          <surface>
            <contact>
              <ode/>
            </contact>
            <bounce/>
            <friction>
              <torsional>
                <ode/>
              </torsional>
              <ode/>
            </friction>
          </surface>
        </collision>
        <visual name='rf_hip_link_visual'>
          <pose>0 0 0 3.14159 -0 0</pose>
          <geometry>
            <mesh>
              <scale>1 1 1</scale>
              <uri>file:///home/zyme/ros_ws/go2_sim/install/go2_description/share/go2_description/meshes/hip.dae</uri>
            </mesh>
          </geometry>
        </visual>
        <self_collide>0</self_collide>
        <enable_wind>0</enable_wind>
        <kinematic>0</kinematic>
      </link>
      <joint name='rf_upper_leg_joint' type='revolute'>
        <pose relative_to='rf_hip_link'>0 -0.0955 0 0 -0 0</pose>
        <parent>rf_hip_link</parent>
        <child>rf_upper_leg_link</child>
        <axis>
          <xyz>0 1 0</xyz>
          <limit>
            <lower>-1.5708</lower>
            <upper>3.4907</upper>
            <effort>23.7</effort>
            <velocity>30.1</velocity>
          </limit>
          <dynamics>
            <damping>0.01</damping>
            <friction>0.2</friction>
            <spring_reference>0</spring_reference>
            <spring_stiffness>0</spring_stiffness>
          </dynamics>
        </axis>
      </joint>
      <link name='rf_upper_leg_link'>
        <pose relative_to='rf_upper_leg_joint'>0 0 0 0 -0 0</pose>
        <inertial>
          <pose>-0.00374 0.0223 -0.0327 0 -0 0</pose>
          <mass>1.152</mass>
          <inertia>
            <ixx>0.00584</ixx>
            <ixy>-8.72e-05</ixy>
            <ixz>-0.000289</ixz>
            <iyy>0.0058</iyy>
            <iyz>-0.000808</iyz>
            <izz>0.00103</izz>
          </inertia>
        </inertial>
        <collision name='rf_upper_leg_link_collision'>
          <pose>0 0 -0.1065 3.14159 1.57079 3.14159</pose>
          <geometry>
            <box>
              <size>0.213 0.0245 0.034</size>
            </box>
          </geometry>
          <surface>
            <contact>
              <ode>
                <kp>10000</kp>
                <kd>1</kd>
              </ode>
            </contact>
            <friction>
              <ode>
                <mu>0.2</mu>
                <mu2>0.2</mu2>
              </ode>
              <torsional>
                <ode/>
              </torsional>
            </friction>
            <bounce/>
          </surface>
          <max_contacts>10</max_contacts>
        </collision>
        <visual name='rf_upper_leg_link_visual'>
          <pose>0 0 0 0 -0 0</pose>
          <geometry>
            <mesh>
              <scale>1 1 1</scale>
              <uri>file:///home/zyme/ros_ws/go2_sim/install/go2_description/share/go2_description/meshes/thigh_mirror.dae</uri>
            </mesh>
          </geometry>
        </visual>
        <self_collide>1</self_collide>
        <enable_wind>0</enable_wind>
        <kinematic>0</kinematic>
      </link>
      <joint name='rf_lower_leg_joint' type='revolute'>
        <pose relative_to='rf_upper_leg_link'>0 0 -0.213 0 -0 0</pose>
        <parent>rf_upper_leg_link</parent>
        <child>rf_lower_leg_link</child>
        <axis>
          <xyz>0 1 0</xyz>
          <limit>
            <lower>-2.7227</lower>
            <upper>-0.83776</upper>
            <effort>35.55</effort>
            <velocity>20.06</velocity>
          </limit>
          <dynamics>
            <damping>0.01</damping>
            <friction>0.2</friction>
            <spring_reference>0</spring_reference>
            <spring_stiffness>0</spring_stiffness>
          </dynamics>
        </axis>
      </joint>
      <link name='rf_lower_leg_link'>
        <pose relative_to='rf_lower_leg_joint'>0 0 0 0 -0 0</pose>
        <inertial>
          <pose>0.003944 -0.000702 -0.142477 0 -0 0</pose>
          <mass>0.214</mass>
          <inertia>
            <ixx>0.00150432</ixx>
            <ixy>5.70698e-07</ixy>
            <ixz>-5.98808e-06</ixz>
            <iyy>0.00152557</iyy>
            <iyz>1.24056e-05</iyz>
            <izz>4.38377e-05</izz>
          </inertia>
        </inertial>
        <collision name='rf_lower_leg_link_collision'>
          <pose>0 0 -0.1065 3.14159 1.57079 3.14159</pose>
          <geometry>
            <box>
              <size>0.213 0.016 0.016</size>
            </box>
          </geometry>
          <surface>
            <contact>
              <ode/>
            </contact>
            <friction>
              <ode>
                <mu>0.2</mu>
                <mu2>0.2</mu2>
              </ode>
              <torsional>
                <ode/>
              </torsional>
            </friction>
            <bounce/>
          </surface>
          <max_contacts>10</max_contacts>
        </collision>
        <collision name='rf_lower_leg_link_fixed_joint_lump__rf_foot_link_collision_1'>
          <pose>0 0 -0.213 0 -0 0</pose>
          <geometry>
            <sphere>
              <radius>0.02</radius>
            </sphere>
          </geometry>
          <surface>
            <contact>
              <ode>
                <kp>10000</kp>
                <kd>1</kd>
              </ode>
            </contact>
            <friction>
              <ode>
                <mu>0.6</mu>
                <mu2>0.6</mu2>
              </ode>
              <torsional>
                <ode/>
              </torsional>
            </friction>
            <bounce/>
          </surface>
          <max_contacts>10</max_contacts>
        </collision>
        <visual name='rf_lower_leg_link_visual'>
          <pose>0 0 0 0 -0 0</pose>
          <geometry>
            <mesh>
              <scale>1 1 1</scale>
              <uri>file:///home/zyme/ros_ws/go2_sim/install/go2_description/share/go2_description/meshes/calf.dae</uri>
            </mesh>
          </geometry>
        </visual>
        <visual name='rf_lower_leg_link_fixed_joint_lump__rf_foot_link_visual_1'>
          <pose>0 0 -0.213 0 -0 0</pose>
          <geometry>
            <sphere>
              <radius>0.01</radius>
            </sphere>
          </geometry>
        </visual>
        <self_collide>1</self_collide>
        <self_collide>1</self_collide>
        <enable_wind>0</enable_wind>
        <kinematic>0</kinematic>
      </link>
      <joint name='rh_hip_joint' type='revolute'>
        <pose relative_to='base_link'>-0.1934 -0.0465 0 0 -0 0</pose>
        <parent>base_link</parent>
        <child>rh_hip_link</child>
        <axis>
          <xyz>1 0 0</xyz>
          <limit>
            <lower>-1.0472</lower>
            <upper>1.0472</upper>
            <effort>23.7</effort>
            <velocity>30.1</velocity>
          </limit>
          <dynamics>
            <damping>0.01</damping>
            <friction>0.2</friction>
            <spring_reference>0</spring_reference>
            <spring_stiffness>0</spring_stiffness>
          </dynamics>
        </axis>
      </joint>
      <link name='rh_hip_link'>
        <pose relative_to='rh_hip_joint'>0 0 0 0 -0 0</pose>
        <inertial>
          <pose>0.0054 -0.00194 -0.000105 0 -0 0</pose>
          <mass>0.678</mass>
          <inertia>
            <ixx>0.00048</ixx>
            <ixy>-3.01e-06</ixy>
            <ixz>-1.11e-06</ixz>
            <iyy>0.000884</iyy>
            <iyz>1.42e-06</iyz>
            <izz>0.000596</izz>
          </inertia>
        </inertial>
        <collision name='rh_hip_link_collision'>
          <pose>0 -0.0955 0 1.5708 -0 0</pose>
          <geometry>
            <cylinder>
              <length>0.04</length>
              <radius>0.046</radius>
            </cylinder>
          </geometry>
          <max_contacts>10</max_contacts>
          <surface>
            <contact>
              <ode/>
            </contact>
            <bounce/>
            <friction>
              <torsional>
                <ode/>
              </torsional>
              <ode/>
            </friction>
          </surface>
        </collision>
        <visual name='rh_hip_link_visual'>
          <pose>0 0 0 0 -0 3.14159</pose>
          <geometry>
            <mesh>
              <scale>1 1 1</scale>
              <uri>file:///home/zyme/ros_ws/go2_sim/install/go2_description/share/go2_description/meshes/hip.dae</uri>
            </mesh>
          </geometry>
        </visual>
        <self_collide>0</self_collide>
        <enable_wind>0</enable_wind>
        <kinematic>0</kinematic>
      </link>
      <joint name='rh_upper_leg_joint' type='revolute'>
        <pose relative_to='rh_hip_link'>0 -0.0955 0 0 -0 0</pose>
        <parent>rh_hip_link</parent>
        <child>rh_upper_leg_link</child>
        <axis>
          <xyz>0 1 0</xyz>
          <limit>
            <lower>-1.5708</lower>
            <upper>3.4907</upper>
            <effort>23.7</effort>
            <velocity>30.1</velocity>
          </limit>
          <dynamics>
            <damping>0.01</damping>
            <friction>0.2</friction>
            <spring_reference>0</spring_reference>
            <spring_stiffness>0</spring_stiffness>
          </dynamics>
        </axis>
      </joint>
      <link name='rh_upper_leg_link'>
        <pose relative_to='rh_upper_leg_joint'>0 0 0 0 -0 0</pose>
        <inertial>
          <pose>-0.00374 0.0223 -0.0327 0 -0 0</pose>
          <mass>1.152</mass>
          <inertia>
            <ixx>0.00584</ixx>
            <ixy>-8.72e-05</ixy>
            <ixz>-0.000289</ixz>
            <iyy>0.0058</iyy>
            <iyz>-0.000808</iyz>
            <izz>0.00103</izz>
          </inertia>
        </inertial>
        <collision name='rh_upper_leg_link_collision'>
          <pose>0 0 -0.1065 3.14159 1.57079 3.14159</pose>
          <geometry>
            <box>
              <size>0.213 0.0245 0.034</size>
            </box>
          </geometry>
          <surface>
            <contact>
              <ode>
                <kp>10000</kp>
                <kd>1</kd>
              </ode>
            </contact>
            <friction>
              <ode>
                <mu>0.2</mu>
                <mu2>0.2</mu2>
              </ode>
              <torsional>
                <ode/>
              </torsional>
            </friction>
            <bounce/>
          </surface>
          <max_contacts>10</max_contacts>
        </collision>
        <visual name='rh_upper_leg_link_visual'>
          <pose>0 0 0 0 -0 0</pose>
          <geometry>
            <mesh>
              <scale>1 1 1</scale>
              <uri>file:///home/zyme/ros_ws/go2_sim/install/go2_description/share/go2_description/meshes/thigh_mirror.dae</uri>
            </mesh>
          </geometry>
        </visual>
        <self_collide>1</self_collide>
        <enable_wind>0</enable_wind>
        <kinematic>0</kinematic>
      </link>
      <joint name='rh_lower_leg_joint' type='revolute'>
        <pose relative_to='rh_upper_leg_link'>0 0 -0.213 0 -0 0</pose>
        <parent>rh_upper_leg_link</parent>
        <child>rh_lower_leg_link</child>
        <axis>
          <xyz>0 1 0</xyz>
          <limit>
            <lower>-2.7227</lower>
            <upper>-0.83776</upper>
            <effort>35.55</effort>
            <velocity>20.06</velocity>
          </limit>
          <dynamics>
            <damping>0.01</damping>
            <friction>0.2</friction>
            <spring_reference>0</spring_reference>
            <spring_stiffness>0</spring_stiffness>
          </dynamics>
        </axis>
      </joint>
      <link name='rh_lower_leg_link'>
        <pose relative_to='rh_lower_leg_joint'>0 0 0 0 -0 0</pose>
        <inertial>
          <pose>0.003944 -0.000702 -0.142477 0 -0 0</pose>
          <mass>0.214</mass>
          <inertia>
            <ixx>0.00150432</ixx>
            <ixy>5.70698e-07</ixy>
            <ixz>-5.98808e-06</ixz>
            <iyy>0.00152557</iyy>
            <iyz>1.24056e-05</iyz>
            <izz>4.38377e-05</izz>
          </inertia>
        </inertial>
        <collision name='rh_lower_leg_link_collision'>
          <pose>0 0 -0.1065 3.14159 1.57079 3.14159</pose>
          <geometry>
            <box>
              <size>0.213 0.016 0.016</size>
            </box>
          </geometry>
          <surface>
            <contact>
              <ode/>
            </contact>
            <friction>
              <ode>
                <mu>0.2</mu>
                <mu2>0.2</mu2>
              </ode>
              <torsional>
                <ode/>
              </torsional>
            </friction>
            <bounce/>
          </surface>
          <max_contacts>10</max_contacts>
        </collision>
        <collision name='rh_lower_leg_link_fixed_joint_lump__rh_foot_link_collision_1'>
          <pose>0 0 -0.213 0 -0 0</pose>
          <geometry>
            <sphere>
              <radius>0.02</radius>
            </sphere>
          </geometry>
          <surface>
            <contact>
              <ode>
                <kp>10000</kp>
                <kd>1</kd>
              </ode>
            </contact>
            <friction>
              <ode>
                <mu>0.6</mu>
                <mu2>0.6</mu2>
              </ode>
              <torsional>
                <ode/>
              </torsional>
            </friction>
            <bounce/>
          </surface>
          <max_contacts>10</max_contacts>
        </collision>
        <visual name='rh_lower_leg_link_visual'>
          <pose>0 0 0 0 -0 0</pose>
          <geometry>
            <mesh>
              <scale>1 1 1</scale>
              <uri>file:///home/zyme/ros_ws/go2_sim/install/go2_description/share/go2_description/meshes/calf.dae</uri>
            </mesh>
          </geometry>
        </visual>
        <visual name='rh_lower_leg_link_fixed_joint_lump__rh_foot_link_visual_1'>
          <pose>0 0 -0.213 0 -0 0</pose>
          <geometry>
            <sphere>
              <radius>0.01</radius>
            </sphere>
          </geometry>
        </visual>
        <self_collide>1</self_collide>
        <self_collide>1</self_collide>
        <enable_wind>0</enable_wind>
        <kinematic>0</kinematic>
      </link>
      <plugin name='p3d_base_controller' filename='libgazebo_ros_p3d.so'>
        <ros>
          <remapping>odom:=odom/ground_truth</remapping>
        </ros>
        <body_name>base_link</body_name>
        <frame_name>world</frame_name>
        <update_rate>10.0</update_rate>
        <xyz_offset>0 0 0</xyz_offset>
        <rpy_offset>0 0 0</rpy_offset>
        <gaussian_noise>0.01</gaussian_noise>
      </plugin>
      <static>0</static>
      <plugin name='gazebo_ros2_control' filename='libgazebo_ros2_control.so'>
        <parameters>/home/zyme/ros_ws/go2_sim/install/go2_description/share/go2_description/config/ros_control/ros_control.yaml</parameters>
      </plugin>
      <pose>0 0 0.275 0 -0 0</pose>
    </model>
    <model name='custom_wall'>
      <pose>2.75173 3.49602 0 0 -0 0</pose>
      <link name='Wall_12'>
        <collision name='Wall_12_Collision'>
          <geometry>
            <box>
              <size>8.25 0.15 2.5</size>
            </box>
          </geometry>
          <pose>0 0 1.25 0 -0 0</pose>
          <max_contacts>10</max_contacts>
          <surface>
            <contact>
              <ode/>
            </contact>
            <bounce/>
            <friction>
              <torsional>
                <ode/>
              </torsional>
              <ode/>
            </friction>
          </surface>
        </collision>
        <visual name='Wall_12_Visual'>
          <pose>0 0 1.25 0 -0 0</pose>
          <geometry>
            <box>
              <size>8.25 0.15 2.5</size>
            </box>
          </geometry>
          <material>
            <script>
              <uri>file://media/materials/scripts/gazebo.material</uri>
              <name>Gazebo/Grey</name>
            </script>
            <ambient>1 1 1 1</ambient>
          </material>
          <meta>
            <layer>0</layer>
          </meta>
        </visual>
        <pose>3.25 -1.925 0 0 -0 0</pose>
        <self_collide>0</self_collide>
        <enable_wind>0</enable_wind>
        <kinematic>0</kinematic>
      </link>
      <link name='Wall_13'>
        <collision name='Wall_13_Collision'>
          <geometry>
            <box>
              <size>5.5 0.15 2.5</size>
            </box>
          </geometry>
          <pose>0 0 1.25 0 -0 0</pose>
          <max_contacts>10</max_contacts>
          <surface>
            <contact>
              <ode/>
            </contact>
            <bounce/>
            <friction>
              <torsional>
                <ode/>
              </torsional>
              <ode/>
            </friction>
          </surface>
        </collision>
        <visual name='Wall_13_Visual'>
          <pose>0 0 1.25 0 -0 0</pose>
          <geometry>
            <box>
              <size>5.5 0.15 2.5</size>
            </box>
          </geometry>
          <material>
            <script>
              <uri>file://media/materials/scripts/gazebo.material</uri>
              <name>Gazebo/Grey</name>
            </script>
            <ambient>1 1 1 1</ambient>
          </material>
          <meta>
            <layer>0</layer>
          </meta>
        </visual>
        <pose>7.3 0.75 0 0 -0 1.5708</pose>
        <self_collide>0</self_collide>
        <enable_wind>0</enable_wind>
        <kinematic>0</kinematic>
      </link>
      <link name='Wall_14'>
        <collision name='Wall_14_Collision'>
          <geometry>
            <box>
              <size>13.5 0.15 2.5</size>
            </box>
          </geometry>
          <pose>0 0 1.25 0 -0 0</pose>
          <max_contacts>10</max_contacts>
          <surface>
            <contact>
              <ode/>
            </contact>
            <bounce/>
            <friction>
              <torsional>
                <ode/>
              </torsional>
              <ode/>
            </friction>
          </surface>
        </collision>
        <visual name='Wall_14_Visual'>
          <pose>0 0 1.25 0 -0 0</pose>
          <geometry>
            <box>
              <size>13.5 0.15 2.5</size>
            </box>
          </geometry>
          <material>
            <script>
              <uri>file://media/materials/scripts/gazebo.material</uri>
              <name>Gazebo/Grey</name>
            </script>
            <ambient>1 1 1 1</ambient>
          </material>
          <meta>
            <layer>0</layer>
          </meta>
        </visual>
        <pose>0.625 3.425 0 0 -0 3.14159</pose>
        <self_collide>0</self_collide>
        <enable_wind>0</enable_wind>
        <kinematic>0</kinematic>
      </link>
      <link name='Wall_15'>
        <collision name='Wall_15_Collision'>
          <geometry>
            <box>
              <size>9.5 0.15 2.5</size>
            </box>
          </geometry>
          <pose>0 0 1.25 0 -0 0</pose>
          <max_contacts>10</max_contacts>
          <surface>
            <contact>
              <ode/>
            </contact>
            <bounce/>
            <friction>
              <torsional>
                <ode/>
              </torsional>
              <ode/>
            </friction>
          </surface>
        </collision>
        <visual name='Wall_15_Visual'>
          <pose>0 0 1.25 0 -0 0</pose>
          <geometry>
            <box>
              <size>9.5 0.15 2.5</size>
            </box>
          </geometry>
          <material>
            <script>
              <uri>file://media/materials/scripts/gazebo.material</uri>
              <name>Gazebo/Grey</name>
            </script>
            <ambient>1 1 1 1</ambient>
          </material>
          <meta>
            <layer>0</layer>
          </meta>
        </visual>
        <pose>-6.05 -1.25 0 0 -0 -1.5708</pose>
        <self_collide>0</self_collide>
        <enable_wind>0</enable_wind>
        <kinematic>0</kinematic>
      </link>
      <link name='Wall_16'>
        <collision name='Wall_16_Collision'>
          <geometry>
            <box>
              <size>16.25 0.15 2.5</size>
            </box>
          </geometry>
          <pose>0 0 1.25 0 -0 0</pose>
          <max_contacts>10</max_contacts>
          <surface>
            <contact>
              <ode/>
            </contact>
            <bounce/>
            <friction>
              <torsional>
                <ode/>
              </torsional>
              <ode/>
            </friction>
          </surface>
        </collision>
        <visual name='Wall_16_Visual'>
          <pose>0 0 1.25 0 -0 0</pose>
          <geometry>
            <box>
              <size>16.25 0.15 2.5</size>
            </box>
          </geometry>
          <material>
            <script>
              <uri>file://media/materials/scripts/gazebo.material</uri>
              <name>Gazebo/Grey</name>
            </script>
            <ambient>1 1 1 1</ambient>
          </material>
          <meta>
            <layer>0</layer>
          </meta>
        </visual>
        <pose>2 -5.925 0 0 -0 0</pose>
        <self_collide>0</self_collide>
        <enable_wind>0</enable_wind>
        <kinematic>0</kinematic>
      </link>
      <link name='Wall_17'>
        <collision name='Wall_17_Collision'>
          <geometry>
            <box>
              <size>12 0.15 2.5</size>
            </box>
          </geometry>
          <pose>0 0 1.25 0 -0 0</pose>
          <max_contacts>10</max_contacts>
          <surface>
            <contact>
              <ode/>
            </contact>
            <bounce/>
            <friction>
              <torsional>
                <ode/>
              </torsional>
              <ode/>
            </friction>
          </surface>
        </collision>
        <visual name='Wall_17_Visual'>
          <pose>0 0 1.25 0 -0 0</pose>
          <geometry>
            <box>
              <size>12 0.15 2.5</size>
            </box>
          </geometry>
          <material>
            <script>
              <uri>file://media/materials/scripts/gazebo.material</uri>
              <name>Gazebo/Grey</name>
            </script>
            <ambient>1 1 1 1</ambient>
          </material>
          <meta>
            <layer>0</layer>
          </meta>
        </visual>
        <pose>10.05 -0 0 0 -0 1.5708</pose>
        <self_collide>0</self_collide>
        <enable_wind>0</enable_wind>
        <kinematic>0</kinematic>
      </link>
      <link name='Wall_18'>
        <collision name='Wall_18_Collision'>
          <geometry>
            <box>
              <size>20.25 0.15 2.5</size>
            </box>
          </geometry>
          <pose>0 0 1.25 0 -0 0</pose>
          <max_contacts>10</max_contacts>
          <surface>
            <contact>
              <ode/>
            </contact>
            <bounce/>
            <friction>
              <torsional>
                <ode/>
              </torsional>
              <ode/>
            </friction>
          </surface>
        </collision>
        <visual name='Wall_18_Visual'>
          <pose>0 0 1.25 0 -0 0</pose>
          <geometry>
            <box>
              <size>20.25 0.15 2.5</size>
            </box>
          </geometry>
          <material>
            <script>
              <uri>file://media/materials/scripts/gazebo.material</uri>
              <name>Gazebo/Grey</name>
            </script>
            <ambient>1 1 1 1</ambient>
          </material>
          <meta>
            <layer>0</layer>
          </meta>
        </visual>
        <pose>0 5.925 0 0 -0 3.14159</pose>
        <self_collide>0</self_collide>
        <enable_wind>0</enable_wind>
        <kinematic>0</kinematic>
      </link>
      <link name='Wall_19'>
        <collision name='Wall_19_Collision'>
          <geometry>
            <box>
              <size>12 0.15 2.5</size>
            </box>
          </geometry>
          <pose>0 0 1.25 0 -0 0</pose>
          <max_contacts>10</max_contacts>
          <surface>
            <contact>
              <ode/>
            </contact>
            <bounce/>
            <friction>
              <torsional>
                <ode/>
              </torsional>
              <ode/>
            </friction>
          </surface>
        </collision>
        <visual name='Wall_19_Visual'>
          <pose>0 0 1.25 0 -0 0</pose>
          <geometry>
            <box>
              <size>12 0.15 2.5</size>
            </box>
          </geometry>
          <material>
            <script>
              <uri>file://media/materials/scripts/gazebo.material</uri>
              <name>Gazebo/Grey</name>
            </script>
            <ambient>1 1 1 1</ambient>
          </material>
          <meta>
            <layer>0</layer>
          </meta>
        </visual>
        <pose>-10.05 -0 0 0 -0 -1.5708</pose>
        <self_collide>0</self_collide>
        <enable_wind>0</enable_wind>
        <kinematic>0</kinematic>
      </link>
      <link name='Wall_20'>
        <collision name='Wall_20_Collision'>
          <geometry>
            <box>
              <size>4.15 0.15 2.5</size>
            </box>
          </geometry>
          <pose>0 0 1.25 0 -0 0</pose>
          <max_contacts>10</max_contacts>
          <surface>
            <contact>
              <ode/>
            </contact>
            <bounce/>
            <friction>
              <torsional>
                <ode/>
              </torsional>
              <ode/>
            </friction>
          </surface>
        </collision>
        <visual name='Wall_20_Visual'>
          <pose>0 0 1.25 0 -0 0</pose>
          <geometry>
            <box>
              <size>4.15 0.15 2.5</size>
            </box>
          </geometry>
          <material>
            <script>
              <uri>file://media/materials/scripts/gazebo.material</uri>
              <name>Gazebo/Grey</name>
            </script>
            <ambient>1 1 1 1</ambient>
          </material>
          <meta>
            <layer>0</layer>
          </meta>
        </visual>
        <pose>-8.05 -5.925 0 0 -0 0</pose>
        <self_collide>0</self_collide>
        <enable_wind>0</enable_wind>
        <kinematic>0</kinematic>
      </link>
      <static>1</static>
    </model>
  </world>
</sdf>
